<?xml version="1.0" encoding="utf-8"?>
<!-- =================================================================================== -->
<!-- |    This document was autogenerated by xacro from greyh_urdfv3.xacro             | -->
<!-- |    EDITING THIS FILE BY HAND IS NOT RECOMMENDED                                 | -->
<!-- =================================================================================== -->
<robot name="greyh_urdfv3">

  <link name="base_link">
    <inertial>
      <origin rpy="0 0 0" xyz="-0.00042512772851683624 0.004221638435313149 0.015589862245031361"/>
      <mass value="6.554383863160311"/>
      <inertia ixx="0.098759" ixy="-3.7e-05" ixz="-7.8e-05" iyy="0.019695" iyz="0.000685" izz="0.104316"/>
    </inertial>
    <visual>
      <origin rpy="0 0 1.5708" xyz="0 0 0"/>
      <geometry>
        <mesh filename="package://greyh_urdfv3_description/meshes/base_link.stl" scale="0.001 0.001 0.001"/>
      </geometry>
      <material name="silver"/>
    </visual>
    <collision>
      <origin rpy="0 0 0" xyz="0 0 0"/>
      <geometry>
        <mesh filename="package://greyh_urdfv3_description/meshes/base_link.stl" scale="0.001 0.001 0.001"/>
      </geometry>
    </collision>
  </link>
  <link name="rh_hip">
    <inertial>
      <origin rpy="0 0 0" xyz="-0.0005774475532295958 -0.02045456069004066 -0.0109329246527541"/>
      <mass value="0.36497544273328236"/>
      <inertia ixx="0.000106" ixy="-0.0" ixz="1e-06" iyy="8.8e-05" iyz="1e-06" izz="7e-05"/>
    </inertial>
    <visual>
      <origin rpy="0 0 1.5708" xyz="0.1218 0.080703 -0.023266"/>
      <geometry>
        <mesh filename="package://greyh_urdfv3_description/meshes/Servo_top_back_right_1.stl" scale="0.001 0.001 0.001"/>
      </geometry>
      <material name="silver"/>
    </visual>
    <collision>
      <origin rpy="0 0 0" xyz="0.080698 -0.142289 -0.023266"/>
      <geometry>
        <mesh filename="package://greyh_urdfv3_description/meshes/Servo_top_back_right_1.stl" scale="0.001 0.001 0.001"/>
      </geometry>
    </collision>
  </link>
  <link name="lh_hip">
    <inertial>
      <origin rpy="0 0 0" xyz="0.0005773081177468803 -0.02054559851620981 -0.010932924656279847"/>
      <mass value="0.36497544270669313"/>
      <inertia ixx="0.000106" ixy="-0.0" ixz="-1e-06" iyy="8.8e-05" iyz="-1e-06" izz="7e-05"/>
    </inertial>
    <visual>
      <origin rpy="0 0 1.5708" xyz="0.1218 -0.080703 -0.023266"/>
      <geometry>
        <mesh filename="package://greyh_urdfv3_description/meshes/Servo_top_back_left_1.stl" scale="0.001 0.001 0.001"/>
      </geometry>
      <material name="silver"/>
    </visual>
    <collision>
      <origin rpy="0 0 0" xyz="-0.080703 -0.142289 -0.023266"/>
      <geometry>
        <mesh filename="package://greyh_urdfv3_description/meshes/Servo_top_back_left_1.stl" scale="0.001 0.001 0.001"/>
      </geometry>
    </collision>
  </link>
  <link name="lf_hip">
    <inertial>
      <origin rpy="0 0 0" xyz="0.0005773081177797013 -0.0205456303999636 -0.01093292465627984"/>
      <mass value="0.36497544270669446"/>
      <inertia ixx="0.000106" ixy="-0.0" ixz="-1e-06" iyy="8.8e-05" iyz="-1e-06" izz="7e-05"/>
    </inertial>
    <visual>
      <!-- <origin rpy="0 0 0" xyz="-0.080703 0.085811 -0.023266"/> -->
      <origin rpy="0 0 1.5708" xyz="-0.1063 -0.080703 -0.023266"/>
      <geometry>
        <mesh filename="package://greyh_urdfv3_description/meshes/Servo_top_front_left_1.stl" scale="0.001 0.001 0.001"/>
      </geometry>
      <material name="silver"/>
    </visual>
    <collision>
      <origin rpy="0 0 0" xyz="-0.080703 0.085811 -0.023266"/>
      <geometry>
        <mesh filename="package://greyh_urdfv3_description/meshes/Servo_top_front_left_1.stl" scale="0.001 0.001 0.001"/>
      </geometry>
    </collision>
  </link>
  <link name="rf_hip">
    <inertial>
      <origin rpy="0 0 0" xyz="-0.0005774475531919732 -0.020454592573804428 -0.010932924652754182"/>
      <mass value="0.36497544273328253"/>
      <inertia ixx="0.000106" ixy="-0.0" ixz="1e-06" iyy="8.8e-05" iyz="1e-06" izz="7e-05"/>
    </inertial>
    <visual>
      <origin rpy="0 0 1.5708" xyz="-0.1063 0.080703 -0.023266"/>
      <geometry>
        <mesh filename="package://greyh_urdfv3_description/meshes/Servo_top_right_front_1.stl" scale="0.001 0.001 0.001"/>
      </geometry>
      <material name="silver"/>
    </visual>
    <collision>
      <origin rpy="0 0 0" xyz="0.080698 0.085811 -0.023266"/>
      <geometry>
        <mesh filename="package://greyh_urdfv3_description/meshes/Servo_top_right_front_1.stl" scale="0.001 0.001 0.001"/>
      </geometry>
    </collision>
  </link>
  <link name="rf_leg">
    <inertial>
      <origin rpy="0 0 0" xyz="-0.020836314076387474 0.050844295953702955 -0.042522056832365956"/>
      <mass value="1.1847103675731914"/>
      <inertia ixx="0.002514" ixy="1.2e-05" ixz="-1e-05" iyy="0.001363" iyz="0.001144" izz="0.001638"/>
    </inertial>
    <visual>
      <origin rpy="-0.907571 0 1.5708" xyz="-0.0532 0.123 -0.0934"/>
      <geometry>
        <mesh filename="package://greyh_urdfv3_description/meshes/Top_leg_front_right_1.stl" scale="0.001 0.001 0.001"/>
      </geometry>
      <material name="silver"/>
    </visual>
    <collision>
      <origin rpy="0 0 0" xyz="0.101978 0.106311 -0.015516"/>
      <geometry>
        <mesh filename="package://greyh_urdfv3_description/meshes/Top_leg_front_right_1.stl" scale="0.001 0.001 0.001"/>
      </geometry>
    </collision>
  </link>
  <link name="rh_leg">
    <inertial>
      <origin rpy="0 0 0" xyz="-0.020836314076420448 0.050844175983900466 -0.0425220568323678"/>
      <mass value="1.1847103675731914"/>
      <inertia ixx="0.002514" ixy="1.2e-05" ixz="-1e-05" iyy="0.001363" iyz="0.001144" izz="0.001638"/>
    </inertial>
    <visual>
      <origin rpy="-0.907571 0 1.5708" xyz="0.0873 0.123 0.0865"/>
      <geometry>
        <mesh filename="package://greyh_urdfv3_description/meshes/Top_leg_back_right_1.stl" scale="0.001 0.001 0.001"/>
      </geometry>
      <material name="silver"/>
    </visual>
    <collision>
      <origin rpy="0 0 0" xyz="0.101978 -0.121789 -0.015516"/>
      <geometry>
        <mesh filename="package://greyh_urdfv3_description/meshes/Top_leg_back_right_1.stl" scale="0.001 0.001 0.001"/>
      </geometry>
    </collision>
  </link>
  <link name="lf_leg">
    <inertial>
      <origin rpy="0 0 0" xyz="0.020836211137286717 0.050844311873227535 -0.04252207117129895"/>
      <mass value="1.1847100227572713"/>
      <inertia ixx="0.002514" ixy="-1.2e-05" ixz="1e-05" iyy="0.001363" iyz="0.001144" izz="0.001638"/>
    </inertial>
    <visual>
      <origin rpy="-0.907571 0 1.5708" xyz="-0.0532 -0.123 -0.0934"/>
      <geometry>
        <mesh filename="package://greyh_urdfv3_description/meshes/Top_leg_front_left_1.stl" scale="0.001 0.001 0.001"/>
      </geometry>
      <material name="silver"/>
    </visual>
    <collision>
      <origin rpy="0 0 0" xyz="-0.101983 0.106311 -0.015516"/>
      <geometry>
        <mesh filename="package://greyh_urdfv3_description/meshes/Top_leg_front_left_1.stl" scale="0.001 0.001 0.001"/>
      </geometry>
    </collision>
  </link>
  <link name="lh_leg">
    <inertial>
      <origin rpy="0 0 0" xyz="0.0208362111372576 0.05084419190341423 -0.042522071171296534"/>
      <mass value="1.1847100227572713"/>
      <inertia ixx="0.002514" ixy="-1.2e-05" ixz="1e-05" iyy="0.001363" iyz="0.001144" izz="0.001638"/>
    </inertial>
    <visual>
      <origin rpy="-0.907571 0 1.5708" xyz="0.0873 -0.123 0.0865"/>
      <geometry>
        <mesh filename="package://greyh_urdfv3_description/meshes/Top_leg_back_left_1.stl" scale="0.001 0.001 0.001"/>
      </geometry>
      <material name="silver"/>
    </visual>
    <collision>
      <origin rpy="0 0 0" xyz="-0.101983 -0.121789 -0.015516"/>
      <geometry>
        <mesh filename="package://greyh_urdfv3_description/meshes/Top_leg_back_left_1.stl" scale="0.001 0.001 0.001"/>
      </geometry>
    </collision>
  </link>
  <link name="lf_lowleg">
    <inertial>
      <origin rpy="0 0 0" xyz="-0.017674250412893708 -0.035632881583845546 -0.049225936009879775"/>
      <mass value="0.7102156699004443"/>
      <inertia ixx="0.002727" ixy="2e-06" ixz="3e-06" iyy="0.001861" iyz="-0.001211" izz="0.000974"/>
    </inertial>
    <visual>
      <!-- <origin rpy="0 0 -1.5708" xyz="-0.140653 0.006595 0.08644"/> -->
      <origin rpy="0.610865 0 -1.5708" xyz="-0.0442 0.123 0.0745"/>
      <geometry>
        <mesh filename="package://greyh_urdfv3_description/meshes/Lower_leg_front_left_1.stl" scale="0.001 0.001 0.001"/>
      </geometry>
      <material name="silver"/>
    </visual>
    <collision>
      <origin rpy="0 0 0" xyz="-0.140653 0.006595 0.08644"/>
      <geometry>
        <mesh filename="package://greyh_urdfv3_description/meshes/Lower_leg_front_left_1.stl" scale="0.001 0.001 0.001"/>
      </geometry>
    </collision>
  </link>
  <link name="lh_lowleg">
    <inertial>
      <origin rpy="0 0 0" xyz="-0.01767425041291204 -0.03563300155365895 -0.049225936009877416"/>
      <mass value="0.7102156699004443"/>
      <inertia ixx="0.002727" ixy="2e-06" ixz="3e-06" iyy="0.001861" iyz="-0.001211" izz="0.000974"/>
    </inertial>
    <visual>
      <origin rpy="0.610865 0 -1.5708" xyz="-0.231 0.123 -0.0563"/>
      <geometry>
        <mesh filename="package://greyh_urdfv3_description/meshes/Lower_leg_back_left_1.stl" scale="0.001 0.001 0.001"/>
      </geometry>
      <material name="silver"/>
    </visual>
    <collision>
      <origin rpy="0 0 0" xyz="-0.140653 -0.221505 0.08644"/>
      <geometry>
        <mesh filename="package://greyh_urdfv3_description/meshes/Lower_leg_back_left_1.stl" scale="0.001 0.001 0.001"/>
      </geometry>
    </collision>
  </link>
  <link name="rh_lowleg">
    <inertial>
      <origin rpy="0 0 0" xyz="0.019326388704308667 -0.03563300155366442 -0.04922593600987639"/>
      <mass value="0.7102156699004443"/>
      <inertia ixx="0.002727" ixy="2e-06" ixz="3e-06" iyy="0.001861" iyz="-0.001211" izz="0.000974"/>
    </inertial>
    <visual>
      <origin rpy="0.610865 0 -1.5708" xyz="-0.231 -0.123 -0.0563"/>
      <geometry>
        <mesh filename="package://greyh_urdfv3_description/meshes/Lower_leg_back_right_1.stl" scale="0.001 0.001 0.001"/>
      </geometry>
      <material name="silver"/>
    </visual>
    <collision>
      <origin rpy="0 0 0" xyz="0.142148 -0.221505 0.08644"/>
      <geometry>
        <mesh filename="package://greyh_urdfv3_description/meshes/Lower_leg_back_right_1.stl" scale="0.001 0.001 0.001"/>
      </geometry>
    </collision>
  </link>
  <link name="rf_lowleg">
    <inertial>
      <origin rpy="0 0 0" xyz="0.019326388704328998 -0.03563288158386184 -0.049225936009874696"/>
      <mass value="0.7102156699004443"/>
      <inertia ixx="0.002727" ixy="2e-06" ixz="3e-06" iyy="0.001861" iyz="-0.001211" izz="0.000974"/>
    </inertial>
    <visual>
      <origin rpy="0.610865 0 -1.5708" xyz="-0.0442 -0.123 0.0745"/>
      <geometry>
        <mesh filename="package://greyh_urdfv3_description/meshes/Lower_leg_front_right_1.stl" scale="0.001 0.001 0.001"/>
      </geometry>
      <material name="silver"/>
    </visual>
    <collision>
      <origin rpy="0 0 0" xyz="0.142148 0.006595 0.08644"/>
      <geometry>
        <mesh filename="package://greyh_urdfv3_description/meshes/Lower_leg_front_right_1.stl" scale="0.001 0.001 0.001"/>
      </geometry>
    </collision>
  </link>
  <link name="lf_foot"/>
  <link name="rf_foot"/>
  <link name="lh_foot"/>
  <link name="rh_foot"/>
  <joint name="Rev1" type="revolute">
    <origin rpy="0 0 0" xyz="-0.1218 -0.080703 0.023266"/>
    <parent link="base_link"/>
    <child link="rh_hip"/>
    <axis xyz="1 0 0"/>

    <!-- Joint limits -->
    <limit lower="-3.1415" upper="3.1415" velocity="10" effort="100"/>
    <!-- Soft limits -->
    <safety_controller k_position="3"
                    k_velocity="1000"
                    soft_lower_limit="-3.1415"
                    soft_upper_limit="3.1415" />


  </joint>
  <joint name="Rev2" type="continuous">
    <origin rpy="0 0 0" xyz="-0.1218 0.080703 0.023266"/>
    <parent link="base_link"/>
    <child link="lh_hip"/>
    <axis xyz="1 0 0"/>

  </joint>
  <joint name="Rev3" type="continuous">
    <!-- <origin rpy="0 0 0" xyz="0.080703 -0.085811 0.023266"/> -->
    <origin rpy="0 0 0" xyz="0.1065 0.080703 0.023266"/>
    <parent link="base_link"/>
    <child link="lf_hip"/>
    <axis xyz="1 0 0"/>
  </joint>
  <joint name="Rev4" type="continuous">
    <origin rpy="0 0 0" xyz="0.1065 -0.080703 0.023266"/>
    <parent link="base_link"/>
    <child link="rf_hip"/>
    <axis xyz="1 0 0"/>
  </joint>
  <joint name="Rev5" type="continuous">
    <origin rpy="0 0 0" xyz="0 -0.041 -.0075"/>
    <parent link="rf_hip"/>
    <child link="rf_leg"/>
    <axis xyz="0 1 0 "/>
  </joint>
  <joint name="Rev6" type="revolute">
    <origin rpy="0 0 0" xyz="0 -0.041 -.0075"/>
    <parent link="rh_hip"/>
    <child link="rh_leg"/>
    <axis xyz="0 1 0 "/>


    <!-- Joint limits -->
    <limit lower="-3.1415" upper="3.1415" velocity="10" effort="100"/>
    <!-- Soft limits -->
    <safety_controller k_position="3"
                    k_velocity="1000"
                    soft_lower_limit="-3.1415"
                    soft_upper_limit="3.1415" />

  </joint>
  <joint name="Rev7" type="continuous">
    <origin rpy="0 0 0" xyz="0 0.041 -.0075"/>
    <parent link="lf_hip"/>
    <child link="lf_leg"/>
    <axis xyz="0 1 0 "/>
  </joint>
  <joint name="Rev8" type="continuous">
    <origin rpy="0 0 0" xyz="0 0.041 -.0075"/>
    <parent link="lh_hip"/>
    <child link="lh_leg"/>
    <axis xyz="0 1 0 "/>
  </joint>
  <joint name="Rev9" type="continuous">
    <origin rpy="0 0 0" xyz="0.019 0 -0.142"/>
    <parent link="lf_leg"/>
    <child link="lf_lowleg"/>
    <axis xyz="0 1 0 "/>
  </joint>
  <joint name="Rev10" type="continuous">
    <origin rpy="0 0 0" xyz="0.019 0 -0.142"/>
    <parent link="lh_leg"/>
    <child link="lh_lowleg"/>
    <axis xyz="0 1 0 "/>
  </joint>
  <joint name="Rev11" type="revolute">
    <origin rpy="0 0 0" xyz="0.019 0 -0.142"/>
    <parent link="rh_leg"/>
    <child link="rh_lowleg"/>
    <axis xyz="0 1 0 "/>

    <!-- Joint limits -->
    <limit lower="-3.1415" upper="3.1415" velocity="10" effort="100"/>
    <!-- Soft limits -->
    <safety_controller k_position="3"
                    k_velocity="1000"
                    soft_lower_limit="-3.1415"
                    soft_upper_limit="3.1415" />
  </joint>
  <joint name="Rev12" type="continuous">
    <origin rpy="0 0 0" xyz="0.019 0 -0.142"/>
    <parent link="rf_leg"/>
    <child link="rf_lowleg"/>
    <axis xyz="0 1 0 "/>
  </joint>
  <joint name="Rev13" type="fixed">
    <origin rpy="0 0 0" xyz="0 0 -0.176"/>
    <parent link="lf_lowleg"/>
    <child link="lf_foot"/>
  </joint>
  <joint name="Rev14" type="fixed">
    <origin rpy="0 0 0" xyz="0 0 -0.176"/>
    <parent link="lh_lowleg"/>
    <child link="lh_foot"/>
  </joint>
  <joint name="Rev15" type="fixed">
    <origin rpy="0 0 0" xyz="0 0 -0.176"/>
    <parent link="rh_lowleg"/>
    <child link="rh_foot"/>
  </joint>
  <joint name="Rev16" type="fixed">
    <origin rpy="0 0 0" xyz="0 0 -0.176"/>
    <parent link="rf_lowleg"/>
    <child link="rf_foot"/>
  </joint>

  <material name="silver">
    <color rgba="0.700 0.700 0.700 1.000"/>
  </material>
  <transmission name="Rev1_tran">
    <type>transmission_interface/SimpleTransmission</type>
    <joint name="Rev1">
      <hardwareInterface>hardware_interface/EffortJointInterface</hardwareInterface>
    </joint>
    <actuator name="Rev1_actr">
      <hardwareInterface>hardware_interface/EffortJointInterface</hardwareInterface>
      <mechanicalReduction>1</mechanicalReduction>
    </actuator>
  </transmission>
  <transmission name="Rev2_tran">
    <type>transmission_interface/SimpleTransmission</type>
    <joint name="Rev2">
      <hardwareInterface>hardware_interface/EffortJointInterface</hardwareInterface>
    </joint>
    <actuator name="Rev2_actr">
      <hardwareInterface>hardware_interface/EffortJointInterface</hardwareInterface>
      <mechanicalReduction>1</mechanicalReduction>
    </actuator>
  </transmission>
  <transmission name="Rev3_tran">
    <type>transmission_interface/SimpleTransmission</type>
    <joint name="Rev3">
      <hardwareInterface>hardware_interface/EffortJointInterface</hardwareInterface>
    </joint>
    <actuator name="Rev3_actr">
      <hardwareInterface>hardware_interface/EffortJointInterface</hardwareInterface>
      <mechanicalReduction>1</mechanicalReduction>
    </actuator>
  </transmission>
  <transmission name="Rev4_tran">
    <type>transmission_interface/SimpleTransmission</type>
    <joint name="Rev4">
      <hardwareInterface>hardware_interface/EffortJointInterface</hardwareInterface>
    </joint>
    <actuator name="Rev4_actr">
      <hardwareInterface>hardware_interface/EffortJointInterface</hardwareInterface>
      <mechanicalReduction>1</mechanicalReduction>
    </actuator>
  </transmission>
  <transmission name="Rev5_tran">
    <type>transmission_interface/SimpleTransmission</type>
    <joint name="Rev5">
      <hardwareInterface>hardware_interface/EffortJointInterface</hardwareInterface>
    </joint>
    <actuator name="Rev5_actr">
      <hardwareInterface>hardware_interface/EffortJointInterface</hardwareInterface>
      <mechanicalReduction>1</mechanicalReduction>
    </actuator>
  </transmission>
  <transmission name="Rev6_tran">
    <type>transmission_interface/SimpleTransmission</type>
    <joint name="Rev6">
      <hardwareInterface>hardware_interface/EffortJointInterface</hardwareInterface>
    </joint>
    <actuator name="Rev6_actr">
      <hardwareInterface>hardware_interface/EffortJointInterface</hardwareInterface>
      <mechanicalReduction>1</mechanicalReduction>
    </actuator>
  </transmission>
  <transmission name="Rev7_tran">
    <type>transmission_interface/SimpleTransmission</type>
    <joint name="Rev7">
      <hardwareInterface>hardware_interface/EffortJointInterface</hardwareInterface>
    </joint>
    <actuator name="Rev7_actr">
      <hardwareInterface>hardware_interface/EffortJointInterface</hardwareInterface>
      <mechanicalReduction>1</mechanicalReduction>
    </actuator>
  </transmission>
  <transmission name="Rev8_tran">
    <type>transmission_interface/SimpleTransmission</type>
    <joint name="Rev8">
      <hardwareInterface>hardware_interface/EffortJointInterface</hardwareInterface>
    </joint>
    <actuator name="Rev8_actr">
      <hardwareInterface>hardware_interface/EffortJointInterface</hardwareInterface>
      <mechanicalReduction>1</mechanicalReduction>
    </actuator>
  </transmission>
  <transmission name="Rev9_tran">
    <type>transmission_interface/SimpleTransmission</type>
    <joint name="Rev9">
      <hardwareInterface>hardware_interface/EffortJointInterface</hardwareInterface>
    </joint>
    <actuator name="Rev9_actr">
      <hardwareInterface>hardware_interface/EffortJointInterface</hardwareInterface>
      <mechanicalReduction>1</mechanicalReduction>
    </actuator>
  </transmission>
  <transmission name="Rev10_tran">
    <type>transmission_interface/SimpleTransmission</type>
    <joint name="Rev10">
      <hardwareInterface>hardware_interface/EffortJointInterface</hardwareInterface>
    </joint>
    <actuator name="Rev10_actr">
      <hardwareInterface>hardware_interface/EffortJointInterface</hardwareInterface>
      <mechanicalReduction>1</mechanicalReduction>
    </actuator>
  </transmission>
  <transmission name="Rev11_tran">
    <type>transmission_interface/SimpleTransmission</type>
    <joint name="Rev11">
      <hardwareInterface>hardware_interface/EffortJointInterface</hardwareInterface>
    </joint>
    <actuator name="Rev11_actr">
      <hardwareInterface>hardware_interface/EffortJointInterface</hardwareInterface>
      <mechanicalReduction>1</mechanicalReduction>
    </actuator>
  </transmission>
  <transmission name="Rev12_tran">
    <type>transmission_interface/SimpleTransmission</type>
    <joint name="Rev12">
      <hardwareInterface>hardware_interface/EffortJointInterface</hardwareInterface>
    </joint>
    <actuator name="Rev12_actr">
      <hardwareInterface>hardware_interface/EffortJointInterface</hardwareInterface>
      <mechanicalReduction>1</mechanicalReduction>
    </actuator>
  </transmission>
  <gazebo>
    <plugin filename="libgazebo_ros_control.so" name="control"/>
  </gazebo>
  <gazebo reference="base_link">
    <material>Gazebo/Silver</material>
    <mu1>0.2</mu1>
    <mu2>0.2</mu2>
    <selfCollide>true</selfCollide>
    <gravity>true</gravity>
  </gazebo>
  <gazebo reference="Servo_top_back_right_1">
    <material>Gazebo/Silver</material>
    <mu1>0.2</mu1>
    <mu2>0.2</mu2>
    <selfCollide>true</selfCollide>
  </gazebo>
  <gazebo reference="Servo_top_back_left_1">
    <material>Gazebo/Silver</material>
    <mu1>0.2</mu1>
    <mu2>0.2</mu2>
    <selfCollide>true</selfCollide>
  </gazebo>
  <gazebo reference="Servo_top_front_left_1">
    <material>Gazebo/Silver</material>
    <mu1>0.2</mu1>
    <mu2>0.2</mu2>
    <selfCollide>true</selfCollide>
  </gazebo>
  <gazebo reference="Servo_top_right_front_1">
    <material>Gazebo/Silver</material>
    <mu1>0.2</mu1>
    <mu2>0.2</mu2>
    <selfCollide>true</selfCollide>
  </gazebo>
  <gazebo reference="Top_leg_front_right_1">
    <material>Gazebo/Silver</material>
    <mu1>0.2</mu1>
    <mu2>0.2</mu2>
    <selfCollide>true</selfCollide>
  </gazebo>
  <gazebo reference="Top_leg_back_right_1">
    <material>Gazebo/Silver</material>
    <mu1>0.2</mu1>
    <mu2>0.2</mu2>
    <selfCollide>true</selfCollide>
  </gazebo>
  <gazebo reference="Top_leg_front_left_1">
    <material>Gazebo/Silver</material>
    <mu1>0.2</mu1>
    <mu2>0.2</mu2>
    <selfCollide>true</selfCollide>
  </gazebo>
  <gazebo reference="Top_leg_back_left_1">
    <material>Gazebo/Silver</material>
    <mu1>0.2</mu1>
    <mu2>0.2</mu2>
    <selfCollide>true</selfCollide>
  </gazebo>
  <gazebo reference="Lower_leg_front_left_1">
    <material>Gazebo/Silver</material>
    <mu1>0.2</mu1>
    <mu2>0.2</mu2>
    <selfCollide>true</selfCollide>
  </gazebo>
  <gazebo reference="Lower_leg_back_left_1">
    <material>Gazebo/Silver</material>
    <mu1>0.2</mu1>
    <mu2>0.2</mu2>
    <selfCollide>true</selfCollide>
  </gazebo>
  <gazebo reference="Lower_leg_back_right_1">
    <material>Gazebo/Silver</material>
    <mu1>0.2</mu1>
    <mu2>0.2</mu2>
    <selfCollide>true</selfCollide>
  </gazebo>
  <gazebo reference="Lower_leg_front_right_1">
    <material>Gazebo/Silver</material>
    <mu1>0.2</mu1>
    <mu2>0.2</mu2>
    <selfCollide>true</selfCollide>
  </gazebo>
</robot>

